Workbook

Sheet Dashboard
A1: CUSTOMER SUPPORT DASHBOARD
A3: TOTAL TICKETS | D3: RESOLUTION RATE | G3: AVG RESOLUTION TIME | J3: AVG CUSTOMER SATISFACTION | M3: URGENT TICKETS
A4: 500 | D4: 0.638 | G4: 35.90 Hrs | J4: 3.22/5 | M4: 134

Sheet Data Analysis
A1: total tickets | B1: =COUNTA('cleaned data'!A:A)-1 -> 500
A2: resolved tickets | B2: =COUNTIF('cleaned data'!G:G,"resolved") -> 319
A3: pending tickets | B3: =COUNTIF('cleaned data'!G:G,"pending") -> 85
A4: urgent tickets | B4: =COUNTIF('cleaned data'!F:F,"urgent") -> 134
A5: delivery tickets | B5: =COUNTIF('cleaned data'!D:D,"DELIVERY") -> 79
A6: RESOLUTION RATE | B6: =B2/B1 -> 0.638
A8: Urgent and pending tickets | B8: =COUNTIFS('cleaned data'!F:F,"URGENT",'cleaned data'!G:G,"PENDING") -> 26
A9: Delivery tickets that are resolved | B9: =COUNTIFS('cleaned data'!D:D,"delivery",'cleaned data'!G:G,"resolved") -> 52
A10: Technical issues that are urgent | B10: =COUNTIFS('cleaned data'!D:D,"technical",'cleaned data'!F:F,"urgent") -> 0
A13: Observation : There are ___26___ urgent pending tickets, which may require immediate attention.

Sheet cleaned data
A1: ticket_id | B1: created_date | C1: resolved_date | D1: category | E1: channel | F1: priority | G1: status | H1: agent | I1: resolution_time_hours | J1: customer_satisfaction | K1: clean_category | L1: channel_updated
A2: TKT-0112 | B2: 45700.93 | C2: 45701.088 | D2: Technical Issue | E2: Phone | F2: High | G2: Resolved | H2: Priya Sharma | I2: 3.8 | J2: 1 | K2: =TRIM(D2) -> Technical Issue | L2: =TRIM(E2) -> Phone
A3: TKT-0345 | B3: 45737.935 | C3: 45738.127 | D3: Account | E3: Email | F3: Urgent | G3: Resolved | H3: Aisha Khan | I3: 4.6 | J3: 1 | K3: =TRIM(D3) -> Account | L3: =TRIM(E3) -> Email
A4: TKT-0158 | B4: 45714.451 | C4: 45714.701 | D4: Product Information | E4: Chat | F4: High | G4: Resolved | H4: Omar Hassan | I4: 6 | J4: 1 | K4: =TRIM(D4) -> Product Information | L4: =TRIM(E4) -> Chat
A5: TKT-0366 | B5: 45800.983 | C5: 45801.287 | D5: Payment | E5: Email | F5: Low | G5: Resolved | H5: Aisha Khan | I5: 7.3 | J5: 1 | K5: =TRIM(D5) -> Payment | L5: =TRIM(E5) -> Email
A6: TKT-0469 | B6: 45699.405 | C6: 45699.863 | D6: Refund | E6: Phone | F6: Medium | G6: Resolved | H6: Aisha Khan | I6: 11 | J6: 1 | K6: =TRIM(D6) -> Refund | L6: =TRIM(E6) -> Phone
A7: TKT-0389 | B7: 45780.778 | C7: 45781.283 | D7: Delivery | E7: Phone | F7: Low | G7: Resolved | H7: Omar Hassan | I7: 12.1 | J7: 1 | K7: =TRIM(D7) -> Delivery | L7: =TRIM(E7) -> Phone
A8: TKT-0240 | B8: 45692.687 | C8: 45693.283 | D8: Technical Issue | E8: Chat | F8: Urgent | G8: Resolved | H8: Maria Garcia | I8: 14.3 | J8: 1 | K8: =TRIM(D8) -> Technical Issue | L8: =TRIM(E8) -> Chat
A9: TKT-0020 | B9: 45676.944 | C9: 45677.649 | D9: Technical Issue | E9: Email | F9: Medium | G9: Resolved | H9: Maria Garcia | I9: 16.9 | J9: 1 | K9: =TRIM(D9) -> Technical Issue | L9: =TRIM(E9) -> Email
A10: TKT-0342 | B10: 45662.753 | C10: 45663.553 | D10: Delivery | E10: Social Media | F10: High | G10: Resolved | H10: Priya Sharma | I10: 19.2 | J10: 1 | K10: =TRIM(D10) -> Delivery | L10: =TRIM(E10) -> Social Media
A11: TKT-0057 | B11: 45791.653 | C11: 45792.49 | D11: Refund | E11: Phone | F11: Medium | G11: Resolved | H11: Maria Garcia | I11: 20.1 | J11: 1 | K11: =TRIM(D11) -> Refund | L11: =TRIM(E11) -> Phone
A12: TKT-0494 | B12: 45829.844 | C12: 45830.715 | D12: Payment | E12: Phone | F12: Urgent | G12: Resolved | H12: Sarah Ahmed | I12: 20.9 | J12: 1 | K12: =TRIM(D12) -> Payment | L12: =TRIM(E12) -> Phone
A13: TKT-0320 | B13: 45766.158 | C13: 45767.066 | D13: Account | E13: Phone | F13: High | G13: Resolved | H13: Daniel Lee | I13: 21.8 | J13: 1 | K13: =TRIM(D13) -> Account | L13: =TRIM(E13) -> Phone
... A320: TKT-0052 | B320: 45695.001 | C320: 45697.956 | D320: Delivery | E320: Social Media | F320: Urgent | G320: Resolved | H320: James Wilson | I320: 70.9 | J320: 5 | K320: =TRIM(D320) -> Delivery | L320: =TRIM(E320) -> Social Media
A321: TKT-0244 | B321: 45735.782 | C321: 45735.836 | D321: Refund | E321: Phone | F321: Medium | G321: Escalated | H321: Aisha Khan | I321: 1.3 | K321: =TRIM(D321) -> Refund | L321: =TRIM(E321) -> Phone
A322: TKT-0416 | B322: 45726.851 | C322: 45726.931 | D322: Refund | E322: Email | F322: Urgent | G322: Escalated | H322: Fatima Ali | I322: 1.9 | K322: =TRIM(D322) -> Refund | L322: =TRIM(E322) -> Email
A323: TKT-0265 | B323: 45754.901 | C323: 45755.039 | D323: Delivery | E323: Chat | F323: Medium | G323: Escalated | H323: Sarah Ahmed | I323: 3.3 | K323: =TRIM(D323) -> Delivery | L323: =TRIM(E323) -> Chat
A324: TKT-0221 | B324: 45812.684 | C324: 45812.826 | D324: Delivery | E324: Chat | F324: High | G324: Escalated | H324: Sarah Ahmed | I324: 3.4 | K324: =TRIM(D324) -> Delivery | L324: =TRIM(E324) -> Chat
A325: TKT-0364 | B325: 45833.411 | C325: 45833.553 | D325: Technical Issue | E325: Chat | F325: Low | G325: Escalated | H325: James Wilson | I325: 3.4 | K325: =TRIM(D325) -> Technical Issue | L325: =TRIM(E325) -> Chat
A326: TKT-0486 | B326: 45794.028 | C326: 45794.237 | D326: Refund | E326: Email | F326: Low | G326: Escalated | H326: Omar Hassan | I326: 5 | K326: =TRIM(D326) -> Refund | L326: =TRIM(E326) -> Email
A327: TKT-0348 | B327: 45743.553 | C327: 45743.766 | D327: Refund | E327: Email | F327: Urgent | G327: Escalated | H327: Sarah Ahmed | I327: 5.1 | K327: =TRIM(D327) -> Refund | L327: =TRIM(E327) -> Email
A328: TKT-0058 | B328: 45743.456 | C328: 45743.719 | D328: Payment | E328: Chat | F328: Urgent | G328: Escalated | H328: Fatima Ali | I328: 6.3 | K328: =TRIM(D328) -> Payment | L328: =TRIM(E328) -> Chat
A329: TKT-0025 | B329: 45677.619 | C329: 45677.931 | D329: Refund | E329: Email | F329: Low | G329: Escalated | H329: James Wilson | I329: 7.5 | K329: =TRIM(D329) -> Refund | L329: =TRIM(E329) -> Email
A330: TKT-0385 | B330: 45814.319 | C330: 45814.649 | D330: Account | E330: Chat | F330: High | G330: Escalated | H330: Daniel Lee | I330: 7.9 | K330: =TRIM(D330) -> Account | L330: =TRIM(E330) -> Chat
A331: TKT-0239 | B331: 45660.4 | C331: 45660.742 | D331: Technical Issue | E331: Phone | F331: Urgent | G331: Escalated | H331: Sarah Ahmed | I331: 8.2 | K331: =TRIM(D331) -> Technical Issue | L331: =TRIM(E331) -> Phone
A332: TKT-0136 | B332: 45772.481 | C332: 45772.826 | D332: Product Information | E332: Chat | F332: Low | G332: Escalated | H332: Maria Garcia | I332: 8.3 | K332: =TRIM(D332) -> Product Information | L332: =TRIM(E332) -> Chat
... A360: TKT-0157 | B360: 45685.31 | C360: 45686.523 | D360: Delivery | E360: Social Media | F360: High | G360: Escalated | H360: Omar Hassan | I360: 29.1 | K360: =TRIM(D360) -> Delivery | L360: =TRIM(E360) -> Social Media
A361: TKT-0411 | B361: 45674.406 | C361: 45675.627 | E361: Email | F361: Medium | G361: Escalated | H361: James Wilson | I361: 29.3 | K361: =TRIM(D361) | L361: =TRIM(E361) -> Email
A362: TKT-0101 | B362: 45737.708 | C362: 45738.946 | D362: Payment | E362: Email | F362: Urgent | G362: Escalated | H362: Daniel Lee | I362: 29.7 | K362: =TRIM(D362) -> Payment | L362: =TRIM(E362) -> Email
A363: TKT-0214 | B363: 45732.538 | C363: 45733.805 | D363: Payment | E363: Phone | F363: High | G363: Escalated | H363: James Wilson | I363: 30.4 | K363: =TRIM(D363) -> Payment | L363: =TRIM(E363) -> Phone
A364: TKT-0128 | B364: 45829.989 | C364: 45831.26 | D364: Refund | E364: Chat | F364: Urgent | G364: Escalated | H364: Daniel Lee | I364: 30.5 | K364: =TRIM(D364) -> Refund | L364: =TRIM(E364) -> Chat
A365: TKT-0341 | B365: 45691.538 | C365: 45692.813 | D365: Product Information | E365: Chat | F365: Urgent | G365: Escalated | H365: Daniel Lee | I365: 30.6 | K365: =TRIM(D365) -> Product Information | L365: =TRIM(E365) -> Chat
A366: TKT-0249 | B366: 45700.454 | C366: 45701.792 | D366: Refund | E366: Chat | F366: Urgent | G366: Escalated | H366: Daniel Lee | I366: 32.1 | K366: =TRIM(D366) -> Refund | L366: =TRIM(E366) -> Chat
A367: TKT-0455 | B367: 45678.603 | C367: 45679.957 | D367: Account | E367: Social Media | F367: High | G367: Escalated | H367: Daniel Lee | I367: 32.5 | K367: =TRIM(D367) -> Account | L367: =TRIM(E367) -> Social Media
A368: TKT-0054 | B368: 45766.299 | C368: 45767.703 | D368: Product Information | E368: Chat | F368: Low | G368: Escalated | H368: Sarah Ahmed | I368: 33.7 | K368: =TRIM(D368) -> Product Information | L368: =TRIM(E368) -> Chat
A369: TKT-0050 | B369: 45771.884 | C369: 45773.313 | D369: Refund | E369: Chat | F369: Low | G369: Escalated | H369: Maria Garcia | I369: 34.3 | K369: =TRIM(D369) -> Refund | L369: =TRIM(E369) -> Chat
A370: TKT-0281 | B370: 45716.29 | C370: 45717.727 | D370: Delivery | E370: Email | F370: High | G370: Escalated | H370: Aisha Khan | I370: 34.5 | K370: =TRIM(D370) -> Delivery | L370: =TRIM(E370) -> Email
A371: TKT-0011 | B371: 45750.297 | C371: 45751.789 | D371: Delivery | E371: Email | F371: Medium | G371: Escalated | H371: Fatima Ali | I371: 35.8 | K371: =TRIM(D371) -> Delivery | L371: =TRIM(E371) -> Email
A372: TKT-0442 | B372: 45733.21 | C372: 45734.71 | D372: Payment | E372: Social Media | F372: High | G372: Escalated | H372: James Wilson | I372: 36 | K372: =TRIM(D372) -> Payment | L372: =TRIM(E372) -> Social Media
A373: TKT-0436 | B373: 45712.959 | C373: 45714.484 | D373: Delivery | E373: Phone | F373: Low | G373: Escalated | H373: Priya Sharma | I373: 36.6 | K373: =TRIM(D373) -> Delivery | L373: =TRIM(E373) -> Phone
...

Sheet Category analysis with PivotTab
A1: category analyisis
A3: Row Labels | B3: Count of ticket_id
B4: 1
A5: Account | B5: 78
A6: Delivery | B6: 79
A7: Payment | B7: 88
A8: Product Information | B8: 89
A9: Refund | B9: 89
A10: Technical Issue | B10: 76
A11: Grand Total | B11: 500
A19: Observation | B19: The Product Information and Refund categories had the highest number of tickets, with 89 tickets each.
A21: Priority analysis
A23: Row Labels | B23: Count of ticket_id
A24: High | B24: 127
A25: Low | B25: 135
A26: Medium | B26: 104
A27: Urgent | B27: 134
A28: Grand Total | B28: 500
A30: most tickets | B30: Low
A31: urgent tickets | B31: 134
A32: %of urgent | B32: =134/500 -> 0.268
A37: STATUS ANALYSIS
A40: Row Labels | B40: Count of ticket_id
A41: Escalated | B41: 96
A42: Pending | B42: 85
A43: Resolved | B43: 319
A44: Grand Total | B44: 500
A47: RESOLUTION RATE | B47: =319/500 -> 0.638
A51: Resolution time analysis
A53: Row Labels | B53: Average of resolution_time_hours
A54: Account | B54: 38.264063
A55: Delivery | B55: 33.36087
A56: Payment | B56: 36.829167
A57: Product Information | B57: 38.74507
A58: Refund | B58: 31.670513
A59: Technical Issue | B59: 37.443333
A60: Grand Total | B60: 35.918599
A67: Highest average resolution time? | B67: Product information
A68: Lowest average resolution time? | B68: Refund
A69: Difference? | B69: =GETPIVOTDATA("resolution_time_hours",$A$53,"clean_category","Product Information")-GETPIVOTDATA("resolution_time_hours",$A$53,"clean_category","Refund") -> 7.0745576
...
